{
 "cells": [
  {
   "cell_type": "code",
   "execution_count": 14,
   "id": "e2b2e812",
   "metadata": {},
   "outputs": [],
   "source": [
    "from data_utils import load_and_preprocess_data\n",
    "from train_model import train_model\n",
    "\n",
    "def test_model(trained_model, X_test, Y_test):\n",
    "    results = trained_model.evaluate(X_test, Y_test)\n",
    "    print(\"Test Loss:\", results[0])\n",
    "    print(\"Test Accuracy:\", results[1])"
   ]
  },
  {
   "cell_type": "code",
   "execution_count": 15,
   "id": "9e0541e1",
   "metadata": {},
   "outputs": [],
   "source": [
    "X_train, X_test, Y_train, Y_test, label_encoder = load_and_preprocess_data()"
   ]
  },
  {
   "cell_type": "code",
   "execution_count": 7,
   "id": "0e224185",
   "metadata": {},
   "outputs": [
    {
     "name": "stdout",
     "output_type": "stream",
     "text": [
      "Epoch 1/100\n"
     ]
    },
    {
     "ename": "ValueError",
     "evalue": "in user code:\n\n    File \"/Users/harshbalgude/miniconda3/lib/python3.11/site-packages/keras/src/engine/training.py\", line 1401, in train_function  *\n        return step_function(self, iterator)\n    File \"/Users/harshbalgude/miniconda3/lib/python3.11/site-packages/keras/src/engine/training.py\", line 1384, in step_function  **\n        outputs = model.distribute_strategy.run(run_step, args=(data,))\n    File \"/Users/harshbalgude/miniconda3/lib/python3.11/site-packages/keras/src/engine/training.py\", line 1373, in run_step  **\n        outputs = model.train_step(data)\n    File \"/Users/harshbalgude/miniconda3/lib/python3.11/site-packages/keras/src/engine/training.py\", line 1150, in train_step\n        y_pred = self(x, training=True)\n    File \"/Users/harshbalgude/miniconda3/lib/python3.11/site-packages/keras/src/utils/traceback_utils.py\", line 70, in error_handler\n        raise e.with_traceback(filtered_tb) from None\n    File \"/Users/harshbalgude/miniconda3/lib/python3.11/site-packages/keras/src/engine/input_spec.py\", line 253, in assert_input_compatibility\n        raise ValueError(\n\n    ValueError: Exception encountered when calling layer 'resnet18_1d' (type Functional).\n    \n    Input 0 of layer \"conv1d_12\" is incompatible with the layer: expected min_ndim=3, found ndim=2. Full shape received: (None, 1000)\n    \n    Call arguments received by layer 'resnet18_1d' (type Functional):\n      • inputs=tf.Tensor(shape=(None, 1000), dtype=float32)\n      • training=True\n      • mask=None\n",
     "output_type": "error",
     "traceback": [
      "\u001b[0;31m---------------------------------------------------------------------------\u001b[0m",
      "\u001b[0;31mValueError\u001b[0m                                Traceback (most recent call last)",
      "Cell \u001b[0;32mIn[7], line 1\u001b[0m\n\u001b[0;32m----> 1\u001b[0m trained_model \u001b[38;5;241m=\u001b[39m train_model(X_train, Y_train, input_shape\u001b[38;5;241m=\u001b[39m(\u001b[38;5;241m1000\u001b[39m, \u001b[38;5;241m12\u001b[39m), num_classes\u001b[38;5;241m=\u001b[39m\u001b[38;5;241m5\u001b[39m)\n",
      "File \u001b[0;32m~/Desktop/ptb-xl/train_model.py:20\u001b[0m, in \u001b[0;36mtrain_model\u001b[0;34m(X_train, Y_train, input_shape, num_classes)\u001b[0m\n\u001b[1;32m     12\u001b[0m resnet18_1d_model\u001b[38;5;241m.\u001b[39mcompile(\n\u001b[1;32m     13\u001b[0m     optimizer\u001b[38;5;241m=\u001b[39moptimizer,\n\u001b[1;32m     14\u001b[0m     loss\u001b[38;5;241m=\u001b[39m\u001b[38;5;124m'\u001b[39m\u001b[38;5;124mcategorical_crossentropy\u001b[39m\u001b[38;5;124m'\u001b[39m,\n\u001b[1;32m     15\u001b[0m     metrics\u001b[38;5;241m=\u001b[39m[\u001b[38;5;124m'\u001b[39m\u001b[38;5;124maccuracy\u001b[39m\u001b[38;5;124m'\u001b[39m]\n\u001b[1;32m     16\u001b[0m )\n\u001b[1;32m     18\u001b[0m early_stopping \u001b[38;5;241m=\u001b[39m EarlyStopping(monitor\u001b[38;5;241m=\u001b[39m\u001b[38;5;124m'\u001b[39m\u001b[38;5;124mval_loss\u001b[39m\u001b[38;5;124m'\u001b[39m, patience\u001b[38;5;241m=\u001b[39m\u001b[38;5;241m3\u001b[39m, restore_best_weights\u001b[38;5;241m=\u001b[39m\u001b[38;5;28;01mTrue\u001b[39;00m)\n\u001b[0;32m---> 20\u001b[0m resnet18_1d_model\u001b[38;5;241m.\u001b[39mfit(\n\u001b[1;32m     21\u001b[0m     X_train, Y_train,\n\u001b[1;32m     22\u001b[0m     validation_split\u001b[38;5;241m=\u001b[39m\u001b[38;5;241m0.2\u001b[39m,\n\u001b[1;32m     23\u001b[0m     epochs\u001b[38;5;241m=\u001b[39m\u001b[38;5;241m100\u001b[39m,\n\u001b[1;32m     24\u001b[0m     batch_size\u001b[38;5;241m=\u001b[39m\u001b[38;5;241m8\u001b[39m,\n\u001b[1;32m     25\u001b[0m     callbacks\u001b[38;5;241m=\u001b[39m[early_stopping]\n\u001b[1;32m     26\u001b[0m )\n\u001b[1;32m     28\u001b[0m \u001b[38;5;28;01mreturn\u001b[39;00m resnet18_1d_model\n",
      "File \u001b[0;32m~/miniconda3/lib/python3.11/site-packages/keras/src/utils/traceback_utils.py:70\u001b[0m, in \u001b[0;36mfilter_traceback.<locals>.error_handler\u001b[0;34m(*args, **kwargs)\u001b[0m\n\u001b[1;32m     67\u001b[0m     filtered_tb \u001b[38;5;241m=\u001b[39m _process_traceback_frames(e\u001b[38;5;241m.\u001b[39m__traceback__)\n\u001b[1;32m     68\u001b[0m     \u001b[38;5;66;03m# To get the full stack trace, call:\u001b[39;00m\n\u001b[1;32m     69\u001b[0m     \u001b[38;5;66;03m# `tf.debugging.disable_traceback_filtering()`\u001b[39;00m\n\u001b[0;32m---> 70\u001b[0m     \u001b[38;5;28;01mraise\u001b[39;00m e\u001b[38;5;241m.\u001b[39mwith_traceback(filtered_tb) \u001b[38;5;28;01mfrom\u001b[39;00m \u001b[38;5;28;01mNone\u001b[39;00m\n\u001b[1;32m     71\u001b[0m \u001b[38;5;28;01mfinally\u001b[39;00m:\n\u001b[1;32m     72\u001b[0m     \u001b[38;5;28;01mdel\u001b[39;00m filtered_tb\n",
      "File \u001b[0;32m/var/folders/k6/2sv64y2n2x30zc_wwpgjvy4h0000gn/T/__autograph_generated_filem8drss2o.py:15\u001b[0m, in \u001b[0;36mouter_factory.<locals>.inner_factory.<locals>.tf__train_function\u001b[0;34m(iterator)\u001b[0m\n\u001b[1;32m     13\u001b[0m \u001b[38;5;28;01mtry\u001b[39;00m:\n\u001b[1;32m     14\u001b[0m     do_return \u001b[38;5;241m=\u001b[39m \u001b[38;5;28;01mTrue\u001b[39;00m\n\u001b[0;32m---> 15\u001b[0m     retval_ \u001b[38;5;241m=\u001b[39m ag__\u001b[38;5;241m.\u001b[39mconverted_call(ag__\u001b[38;5;241m.\u001b[39mld(step_function), (ag__\u001b[38;5;241m.\u001b[39mld(\u001b[38;5;28mself\u001b[39m), ag__\u001b[38;5;241m.\u001b[39mld(iterator)), \u001b[38;5;28;01mNone\u001b[39;00m, fscope)\n\u001b[1;32m     16\u001b[0m \u001b[38;5;28;01mexcept\u001b[39;00m:\n\u001b[1;32m     17\u001b[0m     do_return \u001b[38;5;241m=\u001b[39m \u001b[38;5;28;01mFalse\u001b[39;00m\n",
      "\u001b[0;31mValueError\u001b[0m: in user code:\n\n    File \"/Users/harshbalgude/miniconda3/lib/python3.11/site-packages/keras/src/engine/training.py\", line 1401, in train_function  *\n        return step_function(self, iterator)\n    File \"/Users/harshbalgude/miniconda3/lib/python3.11/site-packages/keras/src/engine/training.py\", line 1384, in step_function  **\n        outputs = model.distribute_strategy.run(run_step, args=(data,))\n    File \"/Users/harshbalgude/miniconda3/lib/python3.11/site-packages/keras/src/engine/training.py\", line 1373, in run_step  **\n        outputs = model.train_step(data)\n    File \"/Users/harshbalgude/miniconda3/lib/python3.11/site-packages/keras/src/engine/training.py\", line 1150, in train_step\n        y_pred = self(x, training=True)\n    File \"/Users/harshbalgude/miniconda3/lib/python3.11/site-packages/keras/src/utils/traceback_utils.py\", line 70, in error_handler\n        raise e.with_traceback(filtered_tb) from None\n    File \"/Users/harshbalgude/miniconda3/lib/python3.11/site-packages/keras/src/engine/input_spec.py\", line 253, in assert_input_compatibility\n        raise ValueError(\n\n    ValueError: Exception encountered when calling layer 'resnet18_1d' (type Functional).\n    \n    Input 0 of layer \"conv1d_12\" is incompatible with the layer: expected min_ndim=3, found ndim=2. Full shape received: (None, 1000)\n    \n    Call arguments received by layer 'resnet18_1d' (type Functional):\n      • inputs=tf.Tensor(shape=(None, 1000), dtype=float32)\n      • training=True\n      • mask=None\n"
     ]
    }
   ],
   "source": [
    "trained_model = train_model(X_train, Y_train, input_shape=(1000, 12), num_classes=5)"
   ]
  },
  {
   "cell_type": "code",
   "execution_count": 18,
   "id": "22cbcb3d",
   "metadata": {},
   "outputs": [
    {
     "data": {
      "text/plain": [
       "(12995, 1000)"
      ]
     },
     "execution_count": 18,
     "metadata": {},
     "output_type": "execute_result"
    }
   ],
   "source": [
    "X_train.shape"
   ]
  },
  {
   "cell_type": "code",
   "execution_count": 19,
   "id": "9fde5476",
   "metadata": {},
   "outputs": [
    {
     "ename": "NameError",
     "evalue": "name 'trained_model' is not defined",
     "output_type": "error",
     "traceback": [
      "\u001b[0;31m---------------------------------------------------------------------------\u001b[0m",
      "\u001b[0;31mNameError\u001b[0m                                 Traceback (most recent call last)",
      "Cell \u001b[0;32mIn[19], line 1\u001b[0m\n\u001b[0;32m----> 1\u001b[0m test_model(trained_model, X_test, Y_test)\n",
      "\u001b[0;31mNameError\u001b[0m: name 'trained_model' is not defined"
     ]
    }
   ],
   "source": [
    "test_model(trained_model, X_test, Y_test)"
   ]
  },
  {
   "cell_type": "code",
   "execution_count": null,
   "id": "29e93d1e",
   "metadata": {},
   "outputs": [],
   "source": []
  }
 ],
 "metadata": {
  "kernelspec": {
   "display_name": "Python 3 (ipykernel)",
   "language": "python",
   "name": "python3"
  },
  "language_info": {
   "codemirror_mode": {
    "name": "ipython",
    "version": 3
   },
   "file_extension": ".py",
   "mimetype": "text/x-python",
   "name": "python",
   "nbconvert_exporter": "python",
   "pygments_lexer": "ipython3",
   "version": "3.11.4"
  }
 },
 "nbformat": 4,
 "nbformat_minor": 5
}
